Workbook

Sheet Hoja2
J1: WhsCode | K1: PV_MATPR
A3: Suma de Valorizado | B3: BODEGAS | J3: Etiquetas de fila | K3: Suma de D/stock
A4: Etiquetas de fila | B4: CU_MATPR | C4: EN_MATPR | D4: EN_SATEL | E4: PV_MATPR | F4: Total general | J4: Aceite | K4: 98.549953
A5: Fruta Conserva | B5: 121250.03 | C5: 30824988 | D5: 93493779 | E5: 15050395 | F5: 1.3949041e+08 | J5: Azucar | K5: 28.943586
A6: Mermelada | B6: 2037334.6 | C6: 67453534 | E6: 41521208 | F6: 1.1101208e+08 | J6: Bolsas | K6: 77.922753
A7: Cremas | B7: 184178.76 | C7: 67556357 | E7: 34218073 | F7: 1.0195861e+08 | J7: Caja | K7: 54.115885
A8: Insumo | B8: 323485 | C8: 52910453 | E8: 10493869 | F8: 63727807 | J8: Carton | K8: 871.57637
A9: Chocolate | B9: 2694073.7 | C9: 47970554 | E9: 9987655.9 | F9: 60652283 | J9: Chocolate | K9: 146.70093
A10: Carton | B10: 3925587.8 | C10: 23618909 | E10: 31284974 | F10: 58829471 | J10: Colorante | K10: 33
A11: Cupula | B11: 1372637.3 | C11: 36116191 | E11: 11570966 | F11: 49059794 | J11: Cremas | K11: 284.90898
A12: Margarina | B12: 7238532 | C12: 1369873.4 | D12: 24304005 | E12: 6592639.8 | F12: 39505050 | J12: Cupula | K12: 128.651
A13: Etiquetas | B13: 3174405.6 | C13: 14533910 | E13: 19271260 | F13: 36979576 | J13: Desmoldante | K13: 23.458515
A14: Mix | B14: 9116387.5 | C14: 5055000 | E14: 20442320 | F14: 34613707 | J14: Empaque | K14: 75.728268
A15: Manjar | B15: 8301942.9 | C15: 20547315 | E15: 1539560 | F15: 30388818 | J15: Esencia | K15: 374.54463
A16: Remojo | C16: 9364534.1 | E16: 8801399.8 | F16: 18165934 | J16: Etiquetas | K16: 807.90132
A17: Bolsas | B17: 4034859.8 | C17: 1911595.9 | E17: 4586294 | F17: 10532750 | J17: Film | K17: 1440.6672
A18: Caja | B18: 223399.76 | C18: 7178359.2 | E18: 2135927 | F18: 9537686 | J18: Fruta Congelada | K18: 12.636547
A19: Film | B19: 276552.07 | C19: 2676646.4 | E19: 5570685.7 | F19: 8523884.2 | J19: Fruta Conserva | K19: 1096.4313
A20: Esencia | C20: 4289462.4 | E20: 2928734.3 | F20: 7218196.7 | J20: Galleta | K20: 37.133188
A21: Huevo | B21: 2958696 | E21: 4232000 | F21: 7190696 | J21: Gelatina | K21: 96.025467
B22: 1407750 | C22: 3820020 | E22: 1285710 | F22: 6513480 | J22: Huevo | K22: 6
A23: Desmoldante | E23: 6323700 | F23: 6323700 | J23: Insumo | K23: 70.130334
A24: Fruta Congelada | C24: 2936979 | E24: 2664049 | F24: 5601028 | J24: Jugo | K24: 58.041407
A25: Galleta | C25: 2377636.3 | E25: 1264756.3 | F25: 3642392.7 | J25: Manjar | K25: 14.013168
A26: Azucar | C26: 2483454.2 | E26: 1149914.1 | F26: 3633368.3 | J26: Margarina | K26: 26.783224
A27: Aceite | E27: 3584000 | F27: 3584000 | J27: Mermelada | K27: 311.3352
A28: Gelatina | C28: 2536301.2 | E28: 1044495.3 | F28: 3580796.5 | J28: Mix | K28: 78.039056
A29: Empaque | B29: 90674.803 | C29: 1269360 | E29: 1212600 | F29: 2572634.8 | J29: Propionato | K29: 29.376
A30: Yogurt | C30: 1544043 | E30: 530630 | F30: 2074673 | J30: Remojo | K30: 47.581137
A31: Jugo | C31: 1940530.1 | E31: 84865.039 | F31: 2025395.2 | J31: Yogurt | K31: 4.2584898
A32: Leche condensada | C32: 1341371.8 | F32: 1341371.8 | J32: Total general | K32: 6334.4539
A33: Colorante | E33: 557370 | F33: 557370
A34: Propionato | B34: 271288.06 | E34: 25819.99 | F34: 297108.05
A35: Licor | C35: 116382.87 | F35: 116382.87
A36: Harina | B36: 45450 | F36: 45450
A37: Colorantes | C37: 44489 | F37: 44489
A38: Total general | B38: 47798486 | C38: 4.1378825e+08 | D38: 1.1779778e+08 | E38: 2.4995587e+08 | F38: 8.2934039e+08

Sheet Hoja1
A1: Número de artículo | B1: Descripción del artículo | C1: Código de almacén | D1: Nombre de almacén | E1: En stock | F1: Precio promedio | G1: Valorizado | H1: Fecha | I1: Consumo | J1: familia | K1: D/stock | L1: MINIMO
A2: 405482 | B2: ALMENDRAS FILETEADAS EGC | C2: EN_MATPR | D2: E1-BMP Enea | E2: 146 | F2: 11250.01 | G2: 1642501.5 | H2: =TODAY() -> 46207 | I2: =IFERROR(VLOOKUP(A2,'[1]Consumo SEMANA ENEA'!$F:$EM,138,0),0) -> 0 | J2: =IFERROR(VLOOKUP(A2,Hoja4!A:C,3,0),"") -> Esencia | K2: =IFERROR(+E2/I2,0) -> 0 | L2: =IFERROR(VLOOKUP(A2,'[1]Consumo SEMANA ENEA'!$F:$ES,144,0),0) -> 0
A3: 405682 | B3: ALMENDRAS FILETEADAS TOSTADAS ALTO LA CRUZ | C3: EN_MATPR | D3: E1-BMP Enea | E3: 40 | F3: 10690 | G3: 427600 | H3: =TODAY() -> 46207 | I3: =IFERROR(VLOOKUP(A3,'[1]Consumo SEMANA ENEA'!$F:$EM,138,0),0) -> 10 | J3: =IFERROR(VLOOKUP(A3,Hoja4!A:C,3,0),"") -> Esencia | K3: =IFERROR(+E3/I3,0) -> 4 | L3: =IFERROR(VLOOKUP(A3,'[1]Consumo SEMANA ENEA'!$F:$ES,144,0),0) -> 3.3333333
A4: 405418 | B4: AZUCAR FLOR 5KG MEL ALIMENTOS | C4: EN_MATPR | D4: E1-BMP Enea | E4: 185 | F4: 1371.65 | G4: 253755.25 | H4: =TODAY() -> 46207 | I4: =IFERROR(VLOOKUP(A4,'[1]Consumo SEMANA ENEA'!$F:$EM,138,0),0) -> 65 | J4: =IFERROR(VLOOKUP(A4,Hoja4!A:C,3,0),"") -> Azucar | K4: =IFERROR(+E4/I4,0) -> 2.8461538 | L4: =IFERROR(VLOOKUP(A4,'[1]Consumo SEMANA ENEA'!$F:$ES,144,0),0) -> 21.666667
A5: 104006 | B5: AZUCAR GRANULADA EGC | C5: EN_MATPR | D5: E1-BMP Enea | E5: 2066 | F5: 900 | G5: 1859400 | H5: =TODAY() -> 46207 | I5: =IFERROR(VLOOKUP(A5,'[1]Consumo SEMANA ENEA'!$F:$EM,138,0),0) -> 1247.7368 | J5: =IFERROR(VLOOKUP(A5,Hoja4!A:C,3,0),"") -> Azucar | K5: =IFERROR(+E5/I5,0) -> 1.6557979 | L5: =IFERROR(VLOOKUP(A5,'[1]Consumo SEMANA ENEA'!$F:$ES,144,0),0) -> 623.8684
A6: 404316 | B6: BASE DE TARTALETA SOFT BLANCA PAVESI | C6: EN_MATPR | D6: E1-BMP Enea | E6: 273 | F6: 1646 | G6: 449358 | H6: =TODAY() -> 46207 | I6: =IFERROR(VLOOKUP(A6,'[1]Consumo SEMANA ENEA'!$F:$EM,138,0),0) -> 365.04 | J6: =IFERROR(VLOOKUP(A6,Hoja4!A:C,3,0),"") -> Insumo | K6: =IFERROR(+E6/I6,0) -> 0.74786325 | L6: =IFERROR(VLOOKUP(A6,'[1]Consumo SEMANA ENEA'!$F:$ES,144,0),0) -> 182.52
A7: 405445 | B7: BASE TORTA 15PP ALTA COEXPAN | C7: EN_MATPR | D7: E1-BMP Enea | E7: 96200 | F7: 93.6 | G7: 9004320 | H7: =TODAY() -> 46207 | I7: =IFERROR(VLOOKUP(A7,'[1]Consumo SEMANA ENEA'!$F:$EM,138,0),0) -> 58368.84 | J7: =IFERROR(VLOOKUP(A7,Hoja4!A:C,3,0),"") -> Cupula | K7: =IFERROR(+E7/I7,0) -> 1.6481397 | L7: =IFERROR(VLOOKUP(A7,'[1]Consumo SEMANA ENEA'!$F:$ES,144,0),0) -> 19456.28
A8: 107302 | B8: BELCOLADE AMARGO 55% PURATOS | C8: EN_MATPR | D8: E1-BMP Enea | E8: 245 | F8: 12960 | G8: 3175200 | H8: =TODAY() -> 46207 | I8: =IFERROR(VLOOKUP(A8,'[1]Consumo SEMANA ENEA'!$F:$EM,138,0),0) -> 107.5 | J8: =IFERROR(VLOOKUP(A8,Hoja4!A:C,3,0),"") -> Chocolate | K8: =IFERROR(+E8/I8,0) -> 2.2790698 | L8: =IFERROR(VLOOKUP(A8,'[1]Consumo SEMANA ENEA'!$F:$ES,144,0),0) -> 53.75
A9: 405645 | B9: BIZCOCHO # 20 BLANCO C/AMAPOLAS PAVESI | C9: EN_MATPR | D9: E1-BMP Enea | E9: 44 | F9: 2450 | G9: 107800 | H9: =TODAY() -> 46207 | I9: =IFERROR(VLOOKUP(A9,'[1]Consumo SEMANA ENEA'!$F:$EM,138,0),0) -> 112.375 | J9: =IFERROR(VLOOKUP(A9,Hoja4!A:C,3,0),"") -> Insumo | K9: =IFERROR(+E9/I9,0) -> 0.39154616 | L9: =IFERROR(VLOOKUP(A9,'[1]Consumo SEMANA ENEA'!$F:$ES,144,0),0) -> 56.1875
A10: 400216 | B10: BIZCOCHO CARROT CAKE PAVESI | C10: EN_MATPR | D10: E1-BMP Enea | E10: 45 | F10: 4322 | G10: 194490 | H10: =TODAY() -> 46207 | I10: =IFERROR(VLOOKUP(A10,'[1]Consumo SEMANA ENEA'!$F:$EM,138,0),0) -> 86.363636 | J10: =IFERROR(VLOOKUP(A10,Hoja4!A:C,3,0),"") -> Insumo | K10: =IFERROR(+E10/I10,0) -> 0.52105263 | L10: =IFERROR(VLOOKUP(A10,'[1]Consumo SEMANA ENEA'!$F:$ES,144,0),0) -> 43.181818
A11: 405786 | B11: BLISTER 243BBTA DEANDES | C11: EN_MATPR | D11: E1-BMP Enea | E11: 6000 | F11: 107 | G11: 642000 | H11: =TODAY() -> 46207 | I11: =IFERROR(VLOOKUP(A11,'[1]Consumo SEMANA ENEA'!$F:$EM,138,0),0) -> 0 | J11: =IFERROR(VLOOKUP(A11,Hoja4!A:C,3,0),"") -> Cupula | K11: =IFERROR(+E11/I11,0) -> 0 | L11: =IFERROR(VLOOKUP(A11,'[1]Consumo SEMANA ENEA'!$F:$ES,144,0),0) -> 0
A12: 403338 | B12: BLISTER 7189 1 PASTEL DEANDES | C12: EN_MATPR | D12: E1-BMP Enea | E12: 13800 | F12: 49.44 | G12: 682272 | H12: =TODAY() -> 46207 | I12: =IFERROR(VLOOKUP(A12,'[1]Consumo SEMANA ENEA'!$F:$EM,138,0),0) -> 3488.04 | J12: =IFERROR(VLOOKUP(A12,Hoja4!A:C,3,0),"") -> Cupula | K12: =IFERROR(+E12/I12,0) -> 3.9563766 | L12: =IFERROR(VLOOKUP(A12,'[1]Consumo SEMANA ENEA'!$F:$ES,144,0),0) -> 1162.68
A13: 400205 | B13: BOLSA PEBD 40x42 CM x35 MICRAS | C13: EN_MATPR | D13: E1-BMP Enea | E13: 2000 | F13: 39.29 | G13: 78580 | H13: =TODAY() -> 46207 | I13: =IFERROR(VLOOKUP(A13,'[1]Consumo SEMANA ENEA'!$F:$EM,138,0),0) -> 2571.4286 | J13: =IFERROR(VLOOKUP(A13,Hoja4!A:C,3,0),"") -> Bolsas | K13: =IFERROR(+E13/I13,0) -> 0.77777778 | L13: =IFERROR(VLOOKUP(A13,'[1]Consumo SEMANA ENEA'!$F:$ES,144,0),0) -> 2571.4286
... A28: 107312 | B28: CEREZAS AL JUGO CAMPOS | C28: EN_MATPR | D28: E1-BMP Enea | E28: 469.9 | F28: 5980 | G28: 2810002 | H28: =TODAY() -> 46207 | I28: =IFERROR(VLOOKUP(A28,'[1]Consumo SEMANA ENEA'!$F:$EM,138,0),0) -> 193.16316 | J28: =IFERROR(VLOOKUP(A28,Hoja4!A:C,3,0),"") -> Fruta Conserva | K28: =IFERROR(+E28/I28,0) -> 2.4326585 | L28: =IFERROR(VLOOKUP(A28,'[1]Consumo SEMANA ENEA'!$F:$ES,144,0),0) -> 96.581579
A29: 403336 | B29: CEREZAS AL JUGO DESCAROZADAS TRES ERRES | C29: EN_MATPR | D29: E1-BMP Enea | E29: 57.9 | F29: 5056.18 | G29: 292752.82 | H29: =TODAY() -> 46207 | I29: =IFERROR(VLOOKUP(A29,'[1]Consumo SEMANA ENEA'!$F:$EM,138,0),0) -> 104.14 | J29: Chocolate | K29: =IFERROR(+E29/I29,0) -> 0.55598233 | L29: =IFERROR(VLOOKUP(A29,'[1]Consumo SEMANA ENEA'!$F:$ES,144,0),0) -> 34.713333
A30: 405748 | B30: CHOCOLATE BLANCO SICAO MEL | C30: EN_MATPR | D30: E1-BMP Enea | E30: 170 | F30: 12238 | G30: 2080460 | H30: =TODAY() -> 46207 | I30: =IFERROR(VLOOKUP(A30,'[1]Consumo SEMANA ENEA'!$F:$EM,138,0),0) -> 0 | J30: =IFERROR(VLOOKUP(A30,Hoja4!A:C,3,0),"") | K30: =IFERROR(+E30/I30,0) -> 0 | L30: =IFERROR(VLOOKUP(A30,'[1]Consumo SEMANA ENEA'!$F:$ES,144,0),0) -> 0
A31: 405373 | B31: CINTA BICOLOR BNEGRO #500 | C31: EN_MATPR | D31: E1-BMP Enea | E31: 307.5 | F31: 14167.83 | G31: 4356607.7 | H31: =TODAY() -> 46207 | I31: =IFERROR(VLOOKUP(A31,'[1]Consumo SEMANA ENEA'!$F:$EM,138,0),0) -> 56.24 | J31: =IFERROR(VLOOKUP(A31,Hoja4!A:C,3,0),"") -> Chocolate | K31: =IFERROR(+E31/I31,0) -> 5.4676387 | L31: =IFERROR(VLOOKUP(A31,'[1]Consumo SEMANA ENEA'!$F:$ES,144,0),0) -> 37.493333
A32: 402255 | B32: CINTA DE EMBALAJE 72x100 SOLUTION | C32: EN_MATPR | D32: E1-BMP Enea | E32: 824 | F32: 1290 | G32: 1062960 | H32: =TODAY() -> 46207 | I32: =IFERROR(VLOOKUP(A32,'[1]Consumo SEMANA ENEA'!$F:$EM,138,0),0) -> 271 | J32: =IFERROR(VLOOKUP(A32,Hoja4!A:C,3,0),"") -> Empaque | K32: =IFERROR(+E32/I32,0) -> 3.0405904 | L32: =IFERROR(VLOOKUP(A32,'[1]Consumo SEMANA ENEA'!$F:$ES,144,0),0) -> 135.5
A33: 404309 | B33: CINTA NEGRA GC ZUKKER | C33: EN_MATPR | D33: E1-BMP Enea | E33: 352 | F33: 8885 | G33: 3127520 | H33: =TODAY() -> 46207 | I33: =IFERROR(VLOOKUP(A33,'[1]Consumo SEMANA ENEA'!$F:$EM,138,0),0) -> 218.66667 | J33: =IFERROR(VLOOKUP(A33,Hoja4!A:C,3,0),"") -> Chocolate | K33: =IFERROR(+E33/I33,0) -> 1.6097561 | L33: =IFERROR(VLOOKUP(A33,'[1]Consumo SEMANA ENEA'!$F:$ES,144,0),0) -> 145.77778
A34: 107197 | B34: COBERTURA CHOCOLATE BLANCO | C34: EN_MATPR | D34: E1-BMP Enea | E34: 420 | F34: 5296.65 | G34: 2224593 | H34: =TODAY() -> 46207 | I34: =IFERROR(VLOOKUP(A34,'[1]Consumo SEMANA ENEA'!$F:$EM,138,0),0) -> 56.727273 | J34: =IFERROR(VLOOKUP(A34,Hoja4!A:C,3,0),"") -> Chocolate | K34: =IFERROR(+E34/I34,0) -> 7.4038462 | L34: =IFERROR(VLOOKUP(A34,'[1]Consumo SEMANA ENEA'!$F:$ES,144,0),0) -> 28.363636
A35: 107249 | B35: COBERTURA CHOCOLATES MONEDAS PURATOS | C35: EN_MATPR | D35: E1-BMP Enea | E35: 303 | F35: 3750 | G35: 1136250 | H35: =TODAY() -> 46207 | I35: =IFERROR(VLOOKUP(A35,'[1]Consumo SEMANA ENEA'!$F:$EM,138,0),0) -> 67.769231 | J35: =IFERROR(VLOOKUP(A35,Hoja4!A:C,3,0),"") -> Chocolate | K35: =IFERROR(+E35/I35,0) -> 4.4710556 | L35: =IFERROR(VLOOKUP(A35,'[1]Consumo SEMANA ENEA'!$F:$ES,144,0),0) -> 33.884615
A36: 107134 | B36: COCO RALLADO ALTO LA CRUZ | C36: EN_MATPR | D36: E1-BMP Enea | E36: 240 | F36: 3599.96 | G36: 863990.4 | H36: =TODAY() -> 46207 | I36: =IFERROR(VLOOKUP(A36,'[1]Consumo SEMANA ENEA'!$F:$EM,138,0),0) -> 111.67833 | J36: =IFERROR(VLOOKUP(A36,Hoja4!A:C,3,0),"") -> Esencia | K36: =IFERROR(+E36/I36,0) -> 2.1490292 | L36: =IFERROR(VLOOKUP(A36,'[1]Consumo SEMANA ENEA'!$F:$ES,144,0),0) -> 37.226111
A37: 405747 | B37: COCTEL DE FRUTA CAMPOS | C37: EN_MATPR | D37: E1-BMP Enea | E37: 343.8 | F37: 3703 | G37: 1273091.4 | H37: =TODAY() -> 46207 | I37: =IFERROR(VLOOKUP(A37,'[1]Consumo SEMANA ENEA'!$F:$EM,138,0),0) -> 174.26667 | J37: =IFERROR(VLOOKUP(A37,Hoja4!A:C,3,0),"") -> Fruta conserva | K37: =IFERROR(+E37/I37,0) -> 1.9728386 | L37: =IFERROR(VLOOKUP(A37,'[1]Consumo SEMANA ENEA'!$F:$ES,144,0),0) -> 58.088889
A38: 403355 | B38: COGÑAC TRES PALOS DE 1LT | C38: EN_MATPR | D38: E1-BMP Enea | E38: 56.9 | F38: 1975.94 | G38: 112430.99 | H38: =TODAY() -> 46207 | I38: =IFERROR(VLOOKUP(A38,'[1]Consumo SEMANA ENEA'!$F:$EM,138,0),0) -> 0 | J38: =IFERROR(VLOOKUP(A38,Hoja4!A:C,3,0),"") -> Licor | K38: =IFERROR(+E38/I38,0) -> 0 | L38: =IFERROR(VLOOKUP(A38,'[1]Consumo SEMANA ENEA'!$F:$ES,144,0),0) -> 0
A39: 107320 | B39: COLDFIL PIE DE LIMÓN | C39: EN_MATPR | D39: E1-BMP Enea | E39: 418.5 | F39: 3122 | G39: 1306557 | H39: =TODAY() -> 46207 | I39: =IFERROR(VLOOKUP(A39,'[1]Consumo SEMANA ENEA'!$F:$EM,138,0),0) -> 205.65 | J39: =IFERROR(VLOOKUP(A39,Hoja4!A:C,3,0),"") -> Mermelada | K39: =IFERROR(+E39/I39,0) -> 2.0350109 | L39: =IFERROR(VLOOKUP(A39,'[1]Consumo SEMANA ENEA'!$F:$ES,144,0),0) -> 102.825
A40: 405427 | B40: COLORANTE ARTIFICIAL AMARILLO DUAS RODAS | C40: EN_MATPR | D40: E1-BMP Enea | E40: 5 | F40: 8897.8 | G40: 44489 | H40: =TODAY() -> 46207 | I40: =IFERROR(VLOOKUP(A40,'[1]Consumo SEMANA ENEA'!$F:$EM,138,0),0) -> 0 | J40: =IFERROR(VLOOKUP(A40,Hoja4!A:C,3,0),"") -> Colorantes | K40: =IFERROR(+E40/I40,0) -> 0 | L40: =IFERROR(VLOOKUP(A40,'[1]Consumo SEMANA ENEA'!$F:$ES,144,0),0) -> 0
A41: 107323 | B41: COMBO 88 ALTA 12 PP LISA MOLDES PAC | C41: EN_MATPR | D41: E1-BMP Enea | E41: 4140 | F41: 231.4 | G41: 957996 | H41: =TODAY() -> 46207 | I41: =IFERROR(VLOOKUP(A41,'[1]Consumo SEMANA ENEA'!$F:$EM,138,0),0) -> 792.08333 | J41: =IFERROR(VLOOKUP(A41,Hoja4!A:C,3,0),"") -> Cupula | K41: =IFERROR(+E41/I41,0) -> 5.2267228 | L41: =IFERROR(VLOOKUP(A41,'[1]Consumo SEMANA ENEA'!$F:$ES,144,0),0) -> 264.02778
... A132: 405376 | B132: ETIQUETA CIRCULAR 9cm TORTA SACHER | C132: EN_MATPR | D132: E1-BMP Enea | E132: 10000 | F132: 22.7 | G132: 227000 | H132: =TODAY() -> 46207 | I132: =IFERROR(VLOOKUP(A132,'[1]Consumo SEMANA ENEA'!$F:$EM,138,0),0) -> 4583.3333 | J132: =IFERROR(VLOOKUP(A132,Hoja4!A:C,3,0),"") -> Etiquetas | K132: =IFERROR(+E132/I132,0) -> 2.1818182 | L132: =IFERROR(VLOOKUP(A132,'[1]Consumo SEMANA ENEA'!$F:$ES,144,0),0) -> 4583.3333
A133: 393425 | B133: ETIQUETA CIRCULAR 9cm TORTA SELVA NEGRA VEGANA | C133: EN_MATPR | D133: E1-BMP Enea | E133: 2000 | F133: 22.27 | G133: 44540 | H133: =TODAY() -> 46207 | I133: =IFERROR(VLOOKUP(A133,'[1]Consumo SEMANA ENEA'!$F:$EM,138,0),0) -> 1272.7273 | J133: Etiquetas | K133: =IFERROR(+E133/I133,0) -> 1.5714286 | L133: =IFERROR(VLOOKUP(A133,'[1]Consumo SEMANA ENEA'!$F:$ES,144,0),0) -> 1272.7273
A134: 405614 | B134: ETIQUETA CIRCULAR 9cm TORTA TENTACIÓN DE CHOCOLATE JUMBO | C134: EN_MATPR | D134: E1-BMP Enea | E134: 2000 | F134: 22.7 | G134: 45400 | H134: =TODAY() -> 46207 | I134: =IFERROR(VLOOKUP(A134,'[1]Consumo SEMANA ENEA'!$F:$EM,138,0),0) -> 1777.7778 | J134: Etiquetas | K134: =IFERROR(+E134/I134,0) -> 1.125 | L134: =IFERROR(VLOOKUP(A134,'[1]Consumo SEMANA ENEA'!$F:$ES,144,0),0) -> 1777.7778
A135: 107266 | B135: ETIQUETA CIRCULAR OPCIÓN VEGANA CRISME | C135: EN_MATPR | D135: E1-BMP Enea | E135: 6000 | F135: 13.65 | G135: 81900 | H135: =TODAY() -> 46207 | I135: =IFERROR(VLOOKUP(A135,'[1]Consumo SEMANA ENEA'!$F:$EM,138,0),0) -> 3000 | J135: Etiquetas | K135: =IFERROR(+E135/I135,0) -> 2 | L135: =IFERROR(VLOOKUP(A135,'[1]Consumo SEMANA ENEA'!$F:$ES,144,0),0) -> 3000
A136: 405111 | B136: ETIQUETA CIRCULAR TORTA AMOR | C136: EN_MATPR | D136: E1-BMP Enea | E136: 5000 | F136: 17.17 | G136: 85850 | H136: =TODAY() -> 46207 | I136: =IFERROR(VLOOKUP(A136,'[1]Consumo SEMANA ENEA'!$F:$EM,138,0),0) -> 3571.4286 | J136: =IFERROR(VLOOKUP(A136,Hoja4!A:C,3,0),"") -> Etiquetas | K136: =IFERROR(+E136/I136,0) -> 1.4 | L136: =IFERROR(VLOOKUP(A136,'[1]Consumo SEMANA ENEA'!$F:$ES,144,0),0) -> 3571.4286
A137: 405809 | B137: ETIQUETA IMPRESA 150X35 TRES COLORES + U.V OPP POSTRE SABOR CHOCOLATE Y FRUTOS DEL BOSQUE | C137: EN_MATPR | D137: E1-BMP Enea | E137: 4000 | F137: 17.16 | G137: 68640 | H137: =TODAY() -> 46207 | I137: =IFERROR(VLOOKUP(A137,'[1]Consumo SEMANA ENEA'!$F:$EM,138,0),0) -> 0 | J137: =IFERROR(VLOOKUP(A137,Hoja4!A:C,3,0),"") | K137: =IFERROR(+E137/I137,0) -> 0 | L137: =IFERROR(VLOOKUP(A137,'[1]Consumo SEMANA ENEA'!$F:$ES,144,0),0) -> 0
A138: 405810 | B138: ETIQUETA IMPRESA 150X35 TRES COLORES + U.V OPP POSTRE SABOR LÚCUMA MANJAR | C138: EN_MATPR | D138: E1-BMP Enea | E138: 6000 | F138: 17.16 | G138: 102960 | H138: =TODAY() -> 46207 | I138: =IFERROR(VLOOKUP(A138,'[1]Consumo SEMANA ENEA'!$F:$EM,138,0),0) -> 0 | J138: =IFERROR(VLOOKUP(A138,Hoja4!A:C,3,0),"") | K138: =IFERROR(+E138/I138,0) -> 0 | L138: =IFERROR(VLOOKUP(A138,'[1]Consumo SEMANA ENEA'!$F:$ES,144,0),0) -> 0
A139: 405808 | B139: ETIQUETA IMPRESA 150X35 TRES COLORES + U.V OPP POSTRE SABOR TRES LECHES CON FRAMBUESA | C139: EN_MATPR | D139: E1-BMP Enea | E139: 6000 | F139: 17.16 | G139: 102960 | H139: =TODAY() -> 46207 | I139: =IFERROR(VLOOKUP(A139,'[1]Consumo SEMANA ENEA'!$F:$EM,138,0),0) -> 0 | J139: =IFERROR(VLOOKUP(A139,Hoja4!A:C,3,0),"") | K139: =IFERROR(+E139/I139,0) -> 0 | L139: =IFERROR(VLOOKUP(A139,'[1]Consumo SEMANA ENEA'!$F:$ES,144,0),0) -> 0
A140: 405310 | B140: ETIQUETA OPP TRANSPARENTE 22X32 CRISME | C140: EN_MATPR | D140: E1-BMP Enea | E140: 100000 | F140: 8 | G140: 800000 | H140: =TODAY() -> 46207 | I140: =IFERROR(VLOOKUP(A140,'[1]Consumo SEMANA ENEA'!$F:$EM,138,0),0) -> 2428.5714 | J140: =IFERROR(VLOOKUP(A140,Hoja4!A:C,3,0),"") -> Etiquetas | K140: =IFERROR(+E140/I140,0) -> 41.176471 | L140: =IFERROR(VLOOKUP(A140,'[1]Consumo SEMANA ENEA'!$F:$ES,144,0),0) -> 2428.5714
A141: 405108 | B141: ETIQUETA TORTA MOCACCINO | C141: EN_MATPR | D141: E1-BMP Enea | E141: 7000 | F141: 22.7 | G141: 158900 | H141: =TODAY() -> 46207 | I141: =IFERROR(VLOOKUP(A141,'[1]Consumo SEMANA ENEA'!$F:$EM,138,0),0) -> 4000 | J141: =IFERROR(VLOOKUP(A141,Hoja4!A:C,3,0),"") -> Etiquetas | K141: =IFERROR(+E141/I141,0) -> 1.75 | L141: =IFERROR(VLOOKUP(A141,'[1]Consumo SEMANA ENEA'!$F:$ES,144,0),0) -> 4000
A142: 405644 | B142: ETIQUETA TORTA MERENGUE COOKIES | C142: EN_MATPR | D142: E1-BMP Enea | E142: 4000 | F142: 22.7 | G142: 90800 | H142: =TODAY() -> 46207 | I142: =IFERROR(VLOOKUP(A142,'[1]Consumo SEMANA ENEA'!$F:$EM,138,0),0) -> 1285.7143 | J142: =IFERROR(VLOOKUP(A142,Hoja4!A:C,3,0),"") -> Etiquetas | K142: =IFERROR(+E142/I142,0) -> 3.1111111 | L142: =IFERROR(VLOOKUP(A142,'[1]Consumo SEMANA ENEA'!$F:$ES,144,0),0) -> 1285.7143
A143: 405089 | B143: ETIQUETA TORTA MERENGUE FRAMBUESA CONGELADA | C143: EN_MATPR | D143: E1-BMP Enea | E143: 9000 | F143: 22.7 | G143: 204300 | H143: =TODAY() -> 46207 | I143: =IFERROR(VLOOKUP(A143,'[1]Consumo SEMANA ENEA'!$F:$EM,138,0),0) -> 1750 | J143: =IFERROR(VLOOKUP(A143,Hoja4!A:C,3,0),"") -> Etiquetas | K143: =IFERROR(+E143/I143,0) -> 5.1428571 | L143: =IFERROR(VLOOKUP(A143,'[1]Consumo SEMANA ENEA'!$F:$ES,144,0),0) -> 1750
A144: 405643 | B144: ETIQUETA TORTA MERENGUE LEMON PIE | C144: EN_MATPR | D144: E1-BMP Enea | E144: 4000 | F144: 22.7 | G144: 90800 | H144: =TODAY() -> 46207 | I144: =IFERROR(VLOOKUP(A144,'[1]Consumo SEMANA ENEA'!$F:$EM,138,0),0) -> 1250 | J144: =IFERROR(VLOOKUP(A144,Hoja4!A:C,3,0),"") -> Etiquetas | K144: =IFERROR(+E144/I144,0) -> 3.2 | L144: =IFERROR(VLOOKUP(A144,'[1]Consumo SEMANA ENEA'!$F:$ES,144,0),0) -> 1250
...

Sheet Hoja3
A1: Número de artículo | B1: Descripción del artículo | C1: ENEA | D1: VESPUCIO | E1: CURICO | F1: TIPS
A2: 405482 | B2: ALMENDRAS FILETEADAS EGC | C2: 1 | D2: =IFERROR(VLOOKUP(A2,'[3]Consumo SEMANAL PV '!$B:$B,1,0),0) -> 0 | E2: 0 | F2: =COUNTIF(C2:E2,1) -> 1
A3: 405682 | B3: ALMENDRAS FILETEADAS TOSTADAS ALTO LA CRUZ | C3: 1 | D3: =IFERROR(VLOOKUP(A3,'[3]Consumo SEMANAL PV '!$B:$B,1,0),0) -> 0 | E3: 0 | F3: =COUNTIF(C3:E3,1) -> 1
A4: 405418 | B4: AZUCAR FLOR 5KG MEL ALIMENTOS | C4: 1 | D4: 1 | E4: 0 | F4: =COUNTIF(C4:E4,1) -> 2
A5: 104006 | B5: AZUCAR GRANULADA EGC | C5: 1 | D5: 1 | E5: 0 | F5: =COUNTIF(C5:E5,1) -> 2
A6: 405445 | B6: BASE TORTA 15PP ALTA COEXPAN | C6: 1 | D6: 1 | E6: 1 | F6: =COUNTIF(C6:E6,1) -> 3
A7: 107302 | B7: BELCOLADE AMARGO 55% PURATOS | C7: 1 | D7: =IFERROR(VLOOKUP(A7,'[3]Consumo SEMANAL PV '!$B:$B,1,0),0) -> 0 | E7: 0 | F7: =COUNTIF(C7:E7,1) -> 1
A8: 400216 | B8: BIZCOCHO CARROT CAKE PAVESI | C8: 1 | D8: =IFERROR(VLOOKUP(A8,'[3]Consumo SEMANAL PV '!$B:$B,1,0),0) -> 0 | E8: 0 | F8: =COUNTIF(C8:E8,1) -> 1
A9: 403338 | B9: BLISTER 7189 1 PASTEL DEANDES | C9: 1 | D9: 1 | E9: 0 | F9: =COUNTIF(C9:E9,1) -> 2
A10: 402263 | B10: BOLSA PREPICADA BANDEJA 100*90 COLOR AZUL ASTRA | C10: 1 | D10: 1 | E10: 0 | F10: =COUNTIF(C10:E10,1) -> 2
A11: 400203 | B11: BOLSA PREPICADA BANDEJA (22+60+22)104x90 | C11: 1 | D11: 1 | E11: 1 | F11: =COUNTIF(C11:E11,1) -> 3
A12: 107120 | B12: BRILLO FRIO RTU PURATOS | C12: 1 | D12: 1 | E12: 0 | F12: =COUNTIF(C12:E12,1) -> 2
A13: 101002 | B13: CACAO AMARGO PURATOS | C13: 1 | D13: 1 | E13: 0 | F13: =COUNTIF(C13:E13,1) -> 2
A14: 106401 | B14: CAFE POLVO WINKLER | C14: 1 | D14: 1 | E14: 0 | F14: =COUNTIF(C14:E14,1) -> 2
A15: 107361 | B15: CAJA PTG AZUL 15PP ALTA SYCOR | C15: 1 | D15: 1 | E15: 0 | F15: =COUNTIF(C15:E15,1) -> 2
A16: 107367 | B16: CAJA DE ENCOMIENDA (EN) SYCOR | C16: 1 | D16: 1 | E16: 0 | F16: =COUNTIF(C16:E16,1) -> 2
A17: 107366 | B17: CAJA MADRE DE PLANCHAS (PL) SYCOR | C17: 1 | D17: 1 | E17: 1 | F17: =COUNTIF(C17:E17,1) -> 3
A18: 405696 | B18: CAJA PASTELES 600X325X120 ASTRA | C18: 1 | D18: 1 | E18: 0 | F18: =COUNTIF(C18:E18,1) -> 2
A19: 405503 | B19: CAJA PASTELES ASTRA | C19: 1 | D19: 1 | E19: 0 | F19: =COUNTIF(C19:E19,1) -> 2
A20: 403219 | B20: CAPSULA OVALADA N° 10 ARRIAZA | C20: 1 | D20: 1 | E20: 0 | F20: =COUNTIF(C20:E20,1) -> 2
A21: 405749 | B21: CARAVELLA RELL FRÍO-CALIENTE AVELLANA 13 KG MASTER MARTINI | C21: 1 | D21: =IFERROR(VLOOKUP(A21,'[3]Consumo SEMANAL PV '!$B:$B,1,0),0) -> 0 | E21: 0 | F21: =COUNTIF(C21:E21,1) -> 1
A22: 107312 | B22: CEREZAS AL JUGO CAMPOS | C22: 1 | D22: =IFERROR(VLOOKUP(A22,'[3]Consumo SEMANAL PV '!$B:$B,1,0),0) -> 0 | E22: 0 | F22: =COUNTIF(C22:E22,1) -> 1
A23: 403336 | B23: CEREZAS AL JUGO DESCAROZADAS TRES ERRES | C23: 1 | D23: =IFERROR(VLOOKUP(A23,'[3]Consumo SEMANAL PV '!$B:$B,1,0),0) -> 0 | E23: 0 | F23: =COUNTIF(C23:E23,1) -> 1
A24: 107356 | B24: CHOCOLATE SEMI AMARGO 54% MEL | C24: 1 | D24: 1 | E24: 0 | F24: =COUNTIF(C24:E24,1) -> 2
A25: 405373 | B25: CINTA BICOLOR BNEGRO #500 | C25: 1 | D25: =IFERROR(VLOOKUP(A25,'[3]Consumo SEMANAL PV '!$B:$B,1,0),0) -> 0 | E25: 0 | F25: =COUNTIF(C25:E25,1) -> 1
A26: 402255 | B26: CINTA DE EMBALAJE 72x100 SOLUTION | C26: 1 | D26: 1 | E26: 1 | F26: =COUNTIF(C26:E26,1) -> 3
A27: 404309 | B27: CINTA NEGRA GC ZUKKER | C27: 1 | D27: 1 | E27: 1 | F27: =COUNTIF(C27:E27,1) -> 3
A28: 107197 | B28: COBERTURA CHOCOLATE BLANCO | C28: 1 | D28: 1 | E28: 0 | F28: =COUNTIF(C28:E28,1) -> 2
A29: 107249 | B29: COBERTURA CHOCOLATES MONEDAS PURATOS | C29: 1 | D29: 1 | E29: 0 | F29: =COUNTIF(C29:E29,1) -> 2
A30: 107134 | B30: COCO RALLADO ALTO LA CRUZ | C30: 1 | D30: 1 | E30: 0 | F30: =COUNTIF(C30:E30,1) -> 2
A31: 405747 | B31: COCTEL DE FRUTA CAMPOS | C31: 1 | D31: =IFERROR(VLOOKUP(A31,'[3]Consumo SEMANAL PV '!$B:$B,1,0),0) -> 0 | E31: 0 | F31: =COUNTIF(C31:E31,1) -> 1
A32: 403355 | B32: COGÑAC TRES PALOS DE 1LT | C32: 1 | D32: =IFERROR(VLOOKUP(A32,'[3]Consumo SEMANAL PV '!$B:$B,1,0),0) -> 0 | E32: 0 | F32: =COUNTIF(C32:E32,1) -> 1
A33: 107320 | B33: COLDFIL PIE DE LIMÓN | C33: 1 | D33: 1 | E33: 0 | F33: =COUNTIF(C33:E33,1) -> 2
A34: 405427 | B34: COLORANTE ARTIFICIAL AMARILLO DUAS RODAS | C34: 1 | D34: =IFERROR(VLOOKUP(A34,'[3]Consumo SEMANAL PV '!$B:$B,1,0),0) -> 0 | E34: 0 | F34: =COUNTIF(C34:E34,1) -> 1
A35: 107323 | B35: COMBO 88 ALTA 12 PP LISA MOLDES PAC | C35: 1 | D35: =IFERROR(VLOOKUP(A35,'[3]Consumo SEMANAL PV '!$B:$B,1,0),0) -> 0 | E35: 0 | F35: =COUNTIF(C35:E35,1) -> 1
A36: 107300 | B36: COMBO 88 ALTA 12 PP MOLDES PAC | C36: 1 | D36: 1 | E36: 1 | F36: =COUNTIF(C36:E36,1) -> 3
A37: 405560 | B37: COSTA CHOCOLATE 24X140 GRS CAROZZI | C37: 1 | D37: =IFERROR(VLOOKUP(A37,'[3]Consumo SEMANAL PV '!$B:$B,1,0),0) -> 0 | E37: 0 | F37: =COUNTIF(C37:E37,1) -> 1
A38: 393400 | B38: COVER PASTELERÍA U2 SEMIAMARGO GOTA PURATOS | C38: 1 | D38: =IFERROR(VLOOKUP(A38,'[3]Consumo SEMANAL PV '!$B:$B,1,0),0) -> 0 | E38: 0 | F38: =COUNTIF(C38:E38,1) -> 1
A39: 405559 | B39: CREAM CHEESE BALDE MILKAUT SANTA ROSA | C39: 1 | D39: =IFERROR(VLOOKUP(A39,'[3]Consumo SEMANAL PV '!$B:$B,1,0),0) -> 0 | E39: 0 | F39: =COUNTIF(C39:E39,1) -> 1
A40: 170183 | B40: CREMA AMBIANTE NATA PURATOS | C40: 1 | D40: =IFERROR(VLOOKUP(A40,'[3]Consumo SEMANAL PV '!$B:$B,1,0),0) -> 0 | E40: 0 | F40: =COUNTIF(C40:E40,1) -> 1
...

Sheet Hoja4
A1: artículo | B1: Descripción artículo/serv. | C1: FAMILIA | D1: TIME | E1: proveedore
A2: 100302 | B2: JARABE REMOJO SISA DIWATTS | C2: Remojo | D2: 2 | E2: DIWATTS S.A.
A3: 101002 | B3: CACAO AMARGO PURATOS | C3: Chocolate | D3: 3 | E3: PURATOS DE CHILE SPA
A4: 102103 | B4: PROPIONATO DE SODIO WINKLER | C4: Propionato | D4: 3 | E4: INDUSTRIAS ALIMENTOS WINKLER LIMITADA.
A5: 103006 | B5: MARGARINA HORNITO DIWATTS | C5: Margarina | D5: 3 | E5: DIWATTS S.A.
A6: 103612 | B6: CREMA VEGETAL MASTER MARTINI | C6: Cremas | D6: 3 | E6: MASTER MARTINI SPA
A7: 104006 | B7: AZUCAR GRANULADA EGC | C7: Azucar | D7: 3 | E7: EGC SPA
A8: 104010 | B8: SAL FINA | C8: insumo | D8: 2 | E8: EGC SPA
A9: 106101 | B9: VINAGRE WINKLER | C9: insumo | D9: 5 | E9: INDUSTRIAS ALIMENTOS WINKLER LIMITADA.
A10: 106401 | B10: CAFE POLVO WINKLER | C10: Esencia | D10: 3 | E10: INDUSTRIAS ALIMENTOS WINKLER LIMITADA.
A11: 107000 | B11: CEREZAS AL JUGO DESCAROZADAS FRUCOL | C11: Fruta Conserva | D11: 5 | E11: FRUCOL CHILE S.P.A
A12: 107095 | B12: PURE DE LUCUMA (ET. VERDE) BALDE 4,5 Kg | C12: Mermelada | D12: 2 | E12: MEL ALIMENTOS SPA
A13: 107098 | B13: CREMA PASTELERA ESPECIAL PURATOS | C13: Cremas | D13: 3 | E13: PURATOS DE CHILE SPA
... A343: 405420 | B343: MEDIO DISCO CARTON BLANCO 19,5 JUMBO ARRIAZA | C343: Carton | D343: 6 | E343: PRODUCTOS ARRIAZA LIMITADA
A344: 107329 | B344: PIÑA EN CUBOS | C344: Fruta conserva | D344: 2
A345: 362099 | B345: GRANA DE HOJA | C345: Insumo | D345: 2 | E345: QUINTA SA
A346: 402111 | B346: FILM TRANSPARENTE 685 MM (23CM) BATTISTA | C346: Film | D346: 4 | E346: #N/A
A347: 405306 | B347: RELLENO COCO CREAM BAKELS | C347: Mermelada | D347: 3 | E347: BAKELS CHILE S.A.
A348: 405307 | B348: TRIANGULO NEGRO COCO RALLADO ZUKKER | C348: Chocolate | D348: 4 | E348: ALIMENTOS ZUKKER LTDA.
A349: 404742 | B349: ETIQUETA CIRCULAR 9cm IMPR. TORTA PIÑA COLADA | C349: Etiquetas | D349: 6 | E349: SOCIEDAD CRISME AUTOADHESIVOS SPA
A350: 405401 | B350: ETIQ.CIRCULAR 9cm IMPR. TORTA MERENGUE NOUGAT | C350: Etiquetas | D350: 6 | E350: SOCIEDAD CRISME AUTOADHESIVOS SPA
A351: 104013 | B351: GELATINA S/SABOR ALFA GROUP | C351: Gelatina | D351: 2 | E351: ALFA CHILENA ALIMENTOS LIMITADA.
A352: 405444 | B352: CUPULA TORTA 15 PP ALTA COEXPAN | C352: Cupula | D352: 2 | E352: COEXPAN CHILE SPA
A353: 405445 | B353: BASE TORTA 15PP ALTA COEXPAN | C353: Cupula | D353: 2 | E353: COEXPAN CHILE SPA
A354: 405049 | B354: ETIQUETA AUTOADHESIVA 22X32 POLIPROPILENO (OPP) | C354: Etiquetas | D354: 6 | E354: SOCIEDAD CRISME AUTOADHESIVOS SPA
A355: 403310 | B355: CAJA PTG AZUL 15PP ALTA | C355: Caja | D355: 15 | E355: PAIMASA S.A.
A356: 405383 | B356: ESTUCHE GALLETAS VERA Y GIANNINI | C356: Cupula | D356: 15 | E356: VERA Y GIANNINI IMPRESORES S.A.
A357: 405447 | B357: MERM. LAMARKA MARACUYA BALDE 5 Kg | C357: Mermelada | D357: 2 | E357: MEL ALIMENTOS SPA
A358: 405427 | B358: COLORANTE ARTIFICIAL AMARILLO DUAS RODAS | C358: Colorantes | D358: 9 | E358: DUAS RODAS CHILE SPA
... A412: 107222 | B412: MANTEQUILLA SIN SAL SOPROLE | C412: Margarina | D412: 2 | E412: COMERCIAL SANTA ELENA S.A.
A413: 404313 | B413: LAMINA ACETATO TRANSPARENTE ECOPLASTIC | C413: Carton | D413: 0 | E413: #N/A
A414: 403014 | B414: PAPEL MANTEQUILLA ARRIAZA | C414: Carton | D414: 6 | E414: PRODUCTOS ARRIAZA LIMITADA
A415: MR1005001 | B415: CALEFACTOR CERRADO 250 WATTS 130 VOLT | C415: Carton | D415: 0 | E415: WATTVOLT INGENIERIA Y SERVICIOS SpA
A416: 405132 | B416: BORDE G 18,5 MEDIANO LAS VERTIENTES | C416: Carton | D416: 8 | E416: SOC. INMOBILIARIA Y DE INVERSIONES LAS VERTIENTES SPA.
A417: 405407 | B417: CARAT NUXEL HAZELNUT | C417: Curico | D417: 3 | E417: PURATOS DE CHILE SPA
A418: 405406 | B418: PRALINE ALM-AVELL 50% PURATOS | C418: Curico | D418: 3 | E418: PURATOS DE CHILE SPA
A419: 405405 | B419: PF PRALICRAC CARAM. PURATOS | C419: Curico | D419: 3 | E419: PURATOS DE CHILE SPA
A420: 107289 | B420: HOJARASCA 16CM OBERENA | C420: Insumo | D420: 2 | E420: COMERCIALIZADORA DE ALIMENTOS OBERENA LTDA
A421: 107137 | B421: ALMENDRAS FILETEADAS ALTO LA CRUZ | C421: Esencia | D421: 2 | E421: AGROINDUSTRIAL LAS TRES ERRE LTDA.
A422: 405248 | B422: MIX PANQUEQUE HUEVO POLVO SAN CRISTOBAL | C422: Mix | D422: 3 | E422: COMPAÑIA MOLINERA SAN CRISTOBAL S.A.
...
